## 脱出構文,例外処理,大域脱出

### 問題
基礎問題4  

### 合格教本
3-11 脱出構文、例外処理、大域脱出  

### raise
- raiseは例外を発生させる。そこで処理が中断される。

- 第一引数に例外クラスまたはそのインスタンスを、第二引数にメッセージを指定できる。  
```
raise ArgumentError, "引数が不正です" #=> ArgumentError
raise ArgumentError.new, "引数が不正です" #=> ArgumentError
```

- 例外クラスのコンストラクタでは、メッセージを指定できる。  
```
err = ArgumentError.new("引数が不正です")
raise err #=> ArgumentError
```

- 引数を省略することもできる  
```
raise "実行中にエラーが発生しました" #=> RuntimeError
```

### elseとensure
- elseで例外が発生しなかったときの処理を記述できる。
- ensure節で例外の発生に関わらず、必ず実行する処理を記述できる。

```
begin #begin 節 は 実行 さ れる 
  p 1 
rescue #例外 は 発生 し ない ので rescue 節 は 実行 し ない 
  p 0 
else #rescue 節 が 実行 さ れ ない ので else 節 は 実行 さ れる
  p 2 
ensure #ensure 節 は 必ず 実行 さ れる 
  p 3 
end #1, 2, 3 と 表示
```

### ensureが実行されない例
- begin式全体の評価値は、本体/rescue節／else節のうち 最後に評価された文の値です。また各節において文が存在しなかったときの値 はnilです。いずれにしてもensure節の値は無視されます。  
[ドキュメント begin](https://docs.ruby-lang.org/ja/2.1.0/doc/spec=2fcontrol.html#begin<Paste>)
```
def m
  begin
    puts "begin"
    1
  ensure
    puts "ensure"
    2
  end
end
p m

#=> begin
#=> ensure
#=> 1 (2じゃない！！)
```

### rescue節の実行順
- rescue節を続けて書く場合は、マッチが広くなる順に指定すること
```
begin
  1/0
rescue
  p 1
rescue ZeroDivisionError # この例外処理は実行されない
  p 2
end #=>1
```

### rescue修飾子
- この場合は補足する例外の指定はできない。StanderdErrorしか補足できない  
- rescueで指定された式が実行される 
```
# 通常の例外の書き方
begin
  @user.name
rescue
  "Unkown"
end

# 後置の例外の書き方
@user.name rescue "Unkown"
```
- メソッド内でもrescueは使える
```
def foo
  -1 / 0
rescue
  p1
end

foo #=> 1
```

### 例外クラスの継承ツリー
以下の例外クラスの継承ツリーを覚えておく  
<img width="565" alt="スクリーンショット 2019-11-17 12 36 09" src="https://user-images.githubusercontent.com/33531901/69003671-819c7b00-0949-11ea-9366-c8e371a6bb94.png">

- StandardError以外は即処理が停止する例外ばっかり
- rescueで何も指定しない場合に拾うのはStandardError
- System系のエラーはStandardErrorの下にいないので明示的にrescueしないと拾えない

### 基礎問題4
```
class Err1 < StandardError;end
class Err2 < Err1; end
begin 
  raise Err2 
rescue => e # こっちのrescue節でStandardErrorから派生する全ての例外を対象とする
  puts "StandardError" 
rescue Err2 => ex #Err2、もしくはErr2を継承した例外オブジェクトを対象とするよう書かれている 
  puts ex.class 
end

=> StandardError（7行目は処理されなくて、5行目で処理される）
```

### 模擬試験
```
class Err1 < StandardError; end
class Err2 < Err1; end
begin
  raise Err2
rescue Err1 => ex
  puts ex.class
end

=> Err2

class Err1 < StandardError; end
class Err2 < Err1; end
begin
  raise Err2
rescue Err2 => ex
  puts ex.class
end

=> Err2
```

### rescueにおける引数省略時のエラー捕捉
- StandardErrorを継承したエラーは捕捉される  
```
class MyError1 < StandardError; end

begin
  raise MyError1
rescue => e
  puts "StandardError!!"
end
puts "End"

#=> StandardError!!
#=> End
```

- Exceptionを継承したエラーは捕捉されない  
```
class MyError2 < Exception; end

begin
  raise MyError2
rescue => e
  puts "Exception!!"
end
puts "End"

#=> End
```

### 例外の再発生
- 同じスレッドとブロックで発生した最後の例外は、組み込み変数「$!」で参照することができる。  
- raiseメソッドを引数なしで実行することで、最後に発生した例外を再度発生させることができる。
```
begin
  1/0
rescue ZeroDivisionError
  p $!.class #=> ZeroDivisionError
  raise #ZeroDivisionErrorの再発生
end
```

### retry
- 例外処理を呼び出し元に委ねるのではなく、自分で解決して再度行いたい場合は、retryが便利。
- beginを再実行する。
- ただし、ensureは一回しか実行されない。
```
a = 0

begin
  b = 1 / a
rescue ZeroDivisionError
  a += 1
  retry
ensure
 p b
end #=> 1
```

### exit
- exitはSystemExit例外を発生させる。resucueしないと処理が終了する  
```
begin
  exit
rescue SystemExit
  puts "SystemExit"
end
puts "End"

SystemExit
End
```

## 参考になったブログ
http://tamata78.hatenablog.com/entry/2015/10/20/093000#%E4%BE%8B%E5%A4%96%E5%87%A6%E7%90%86  

















